<?xml version="1.0" ?>
<robot name="franka_orca_left">
  <material name="white">
    <color rgba="1 1 1 1"/>
  </material>
  <material name="grey">
    <color rgba="0.9 0.9 0.9 1"/>
  </material>
  <material name="dark">
    <color rgba="0.3 0.3 0.3 1"/>
  </material>
  <link name="panda_link0">
    <inertial>
      <origin xyz="0 0 0" rpy="0 0 0"/>
      <origin rpy="0 0 0"/>
      <mass value="0.0"/>
      <inertia ixx="0.000000001" ixy="0.000000000" ixz="0.000000000" iyy="0.000000001" iyz="0.000000000" izz="0.000000001"/>
    </inertial>
  </link>
  <link name="panda_link1">
    <inertial>
      <origin xyz="0 0 0" rpy="0 0 0"/>
      <origin rpy="0 0 0"/>
      <mass value="4.97"/>
      <inertia ixx="0.004970000" ixy="0.000000000" ixz="0.000000000" iyy="0.004970000" iyz="0.000000000" izz="0.004970000"/>
    </inertial>
    <visual>
      <origin xyz="0 0 0.095" rpy="0 0 0"/>
      <geometry>
        <cylinder radius="0.06" length="0.19"/>
      </geometry>
      <material name="grey"/>
    </visual>
    <collision>
      <origin xyz="0 0 0.095" rpy="0 0 0"/>
      <geometry>
        <cylinder radius="0.06" length="0.19"/>
      </geometry>
    </collision>
  </link>
  <link name="panda_link2">
    <inertial>
      <origin xyz="0 0 0" rpy="0 0 0"/>
      <origin rpy="0 0 0"/>
      <mass value="0.646"/>
      <inertia ixx="0.000646000" ixy="0.000000000" ixz="0.000000000" iyy="0.000646000" iyz="0.000000000" izz="0.000646000"/>
    </inertial>
    <visual>
      <origin xyz="0 0 0" rpy="0 0 0"/>
      <geometry>
        <sphere radius="0.06"/>
      </geometry>
      <material name="grey"/>
    </visual>
    <collision>
      <origin xyz="0 0 0" rpy="0 0 0"/>
      <geometry>
        <sphere radius="0.06"/>
      </geometry>
    </collision>
  </link>
  <link name="panda_link3">
    <inertial>
      <origin xyz="0 0 0" rpy="0 0 0"/>
      <origin rpy="0 0 0"/>
      <mass value="3.228"/>
      <inertia ixx="0.003228000" ixy="0.000000000" ixz="0.000000000" iyy="0.003228000" iyz="0.000000000" izz="0.003228000"/>
    </inertial>
    <visual>
      <origin xyz="0 0 0.095" rpy="0 0 0"/>
      <geometry>
        <cylinder radius="0.06" length="0.19"/>
      </geometry>
      <material name="grey"/>
    </visual>
    <collision>
      <origin xyz="0 0 0.095" rpy="0 0 0"/>
      <geometry>
        <cylinder radius="0.06" length="0.19"/>
      </geometry>
    </collision>
  </link>
  <link name="panda_link4">
    <inertial>
      <origin xyz="0 0 0" rpy="0 0 0"/>
      <origin rpy="0 0 0"/>
      <mass value="3.587"/>
      <inertia ixx="0.003587000" ixy="0.000000000" ixz="0.000000000" iyy="0.003587000" iyz="0.000000000" izz="0.003587000"/>
    </inertial>
    <visual>
      <origin xyz="0 0 0" rpy="0 0 0"/>
      <geometry>
        <sphere radius="0.06"/>
      </geometry>
      <material name="grey"/>
    </visual>
    <collision>
      <origin xyz="0 0 0" rpy="0 0 0"/>
      <geometry>
        <sphere radius="0.06"/>
      </geometry>
    </collision>
  </link>
  <link name="panda_link5">
    <inertial>
      <origin xyz="0 0 0" rpy="0 0 0"/>
      <origin rpy="0 0 0"/>
      <mass value="1.225"/>
      <inertia ixx="0.001225000" ixy="0.000000000" ixz="0.000000000" iyy="0.001225000" iyz="0.000000000" izz="0.001225000"/>
    </inertial>
    <visual>
      <origin xyz="0 0 0.095" rpy="0 0 0"/>
      <geometry>
        <cylinder radius="0.06" length="0.19"/>
      </geometry>
      <material name="grey"/>
    </visual>
    <collision>
      <origin xyz="0 0 0.095" rpy="0 0 0"/>
      <geometry>
        <cylinder radius="0.06" length="0.19"/>
      </geometry>
    </collision>
  </link>
  <link name="panda_link6">
    <inertial>
      <origin xyz="0 0 0" rpy="0 0 0"/>
      <origin rpy="0 0 0"/>
      <mass value="1.666"/>
      <inertia ixx="0.001666000" ixy="0.000000000" ixz="0.000000000" iyy="0.001666000" iyz="0.000000000" izz="0.001666000"/>
    </inertial>
    <visual>
      <origin xyz="0 0 0" rpy="0 0 0"/>
      <geometry>
        <sphere radius="0.05"/>
      </geometry>
      <material name="grey"/>
    </visual>
    <collision>
      <origin xyz="0 0 0" rpy="0 0 0"/>
      <geometry>
        <sphere radius="0.05"/>
      </geometry>
    </collision>
  </link>
  <link name="panda_link7">
    <inertial>
      <origin xyz="0 0 0" rpy="0 0 0"/>
      <origin rpy="0 0 0"/>
      <mass value="0.735"/>
      <inertia ixx="0.000735000" ixy="0.000000000" ixz="0.000000000" iyy="0.000735000" iyz="0.000000000" izz="0.000735000"/>
    </inertial>
    <visual>
      <origin xyz="0 0 0.03" rpy="0 0 0"/>
      <geometry>
        <cylinder radius="0.04" length="0.06"/>
      </geometry>
      <material name="dark"/>
    </visual>
    <collision>
      <origin xyz="0 0 0.03" rpy="0 0 0"/>
      <geometry>
        <cylinder radius="0.04" length="0.06"/>
      </geometry>
    </collision>
  </link>
  <link name="panda_link8">
    <inertial>
      <origin xyz="0 0 0" rpy="0 0 0"/>
      <origin rpy="0 0 0"/>
      <mass value="0.0"/>
      <inertia ixx="0.000000001" ixy="0.000000000" ixz="0.000000000" iyy="0.000000001" iyz="0.000000000" izz="0.000000001"/>
    </inertial>
  </link>
  <joint name="panda_joint1" type="revolute">
    <parent link="panda_link0"/>
    <child link="panda_link1"/>
    <origin xyz="0 0 0.333" rpy="0 0 0"/>
    <axis xyz="0 0 1"/>
    <limit lower="-2.8973" upper="2.8973" effort="87.0" velocity="2.175"/>
    <dynamics damping="10.0" friction="0.1"/>
  </joint>
  <joint name="panda_joint2" type="revolute">
    <parent link="panda_link1"/>
    <child link="panda_link2"/>
    <origin xyz="0 0 0" rpy="-1.5708 0 0"/>
    <axis xyz="0 0 1"/>
    <limit lower="-1.7628" upper="1.7628" effort="87.0" velocity="2.175"/>
    <dynamics damping="10.0" friction="0.1"/>
  </joint>
  <joint name="panda_joint3" type="revolute">
    <parent link="panda_link2"/>
    <child link="panda_link3"/>
    <origin xyz="0 -0.316 0" rpy="1.5708 0 0"/>
    <axis xyz="0 0 1"/>
    <limit lower="-2.8973" upper="2.8973" effort="87.0" velocity="2.175"/>
    <dynamics damping="10.0" friction="0.1"/>
  </joint>
  <joint name="panda_joint4" type="revolute">
    <parent link="panda_link3"/>
    <child link="panda_link4"/>
    <origin xyz="0.0825 0 0" rpy="1.5708 0 0"/>
    <axis xyz="0 0 1"/>
    <limit lower="-3.0718" upper="-0.0698" effort="87.0" velocity="2.175"/>
    <dynamics damping="10.0" friction="0.1"/>
  </joint>
  <joint name="panda_joint5" type="revolute">
    <parent link="panda_link4"/>
    <child link="panda_link5"/>
    <origin xyz="-0.0825 0.384 0" rpy="-1.5708 0 0"/>
    <axis xyz="0 0 1"/>
    <limit lower="-2.8973" upper="2.8973" effort="87.0" velocity="2.175"/>
    <dynamics damping="10.0" friction="0.1"/>
  </joint>
  <joint name="panda_joint6" type="revolute">
    <parent link="panda_link5"/>
    <child link="panda_link6"/>
    <origin xyz="0 0 0" rpy="1.5708 0 0"/>
    <axis xyz="0 0 1"/>
    <limit lower="-0.0175" upper="3.7525" effort="87.0" velocity="2.175"/>
    <dynamics damping="10.0" friction="0.1"/>
  </joint>
  <joint name="panda_joint7" type="revolute">
    <parent link="panda_link6"/>
    <child link="panda_link7"/>
    <origin xyz="0.088 0 0" rpy="1.5708 0 0"/>
    <axis xyz="0 0 1"/>
    <limit lower="-2.8973" upper="2.8973" effort="87.0" velocity="2.175"/>
    <dynamics damping="10.0" friction="0.1"/>
  </joint>
  <joint name="panda_joint8" type="fixed">
    <parent link="panda_link7"/>
    <child link="panda_link8"/>
    <origin xyz="0 0 0.107" rpy="0 0 0"/>
  </joint>
  <link name="left_root">
    <inertial>
      <origin rpy="0.0 0.0 0.0" xyz="-0.0 0.0 0.0"/>
      <mass value="0.0"/>
      <inertia ixx="0.0" ixy="0" ixz="0" iyy="0.0" iyz="0" izz="0.0"/>
    </inertial>
  </link>
  <link name="left_tower">
    <inertial>
      <origin rpy="-0.0026099999999999977 0.007370000000000099 0.04145" xyz="-0.04034 -0.00091 0.01912"/>
      <mass value="0.9"/>
      <inertia ixx="0.00150422" ixy="0" ixz="0" iyy="0.00125262" iyz="0" izz="0.0007962"/>
    </inertial>
    <visual name="visual_tower_main_mesh">
      <origin rpy="-0.007252153364137093 -0.004356332895580239 1.533990149039079" xyz="-0.04069509610470536 -0.00012511806280993186 0.02312294830988657"/>
      <geometry>
        <mesh filename="orcahand_description/assets/urdf/visual/tower_main_mesh.stl" scale="-1 1 1"/>
      </geometry>
      <material name="white"/>
    </visual>
    <collision name="collision_tower_main_mesh">
      <origin rpy="0.0663641604020242 -0.10532695421927696 -0.7765909134463538" xyz="-0.04102610596606573 0.0008755408110132971 0.03758955025925282"/>
      <geometry>
        <mesh filename="orcahand_description/assets/urdf/collision/tower_main_mesh.stl" scale="-1 1 1"/>
      </geometry>
      <material name="white"/>
    </collision>
    <visual name="visual_tower_hull_mesh">
      <origin rpy="1.5694791585075034 0.00015194814647356836 -0.0006505124711437826" xyz="-0.04062006698890873 -3.726678941555769e-06 0.009339292204050375"/>
      <geometry>
        <mesh filename="orcahand_description/assets/urdf/visual/tower_hull_mesh.stl" scale="-1 1 1"/>
      </geometry>
      <material name="white"/>
    </visual>
    <collision name="collision_tower_hull_mesh">
      <origin rpy="1.5691929949477865 -6.931644826568828e-05 -0.0012916867662787768" xyz="-0.04061884697236149 7.083739226185091e-06 0.009306225228503611"/>
      <geometry>
        <mesh filename="orcahand_description/assets/urdf/collision/tower_hull_mesh.stl" scale="-1 1 1"/>
      </geometry>
      <material name="white"/>
    </collision>
    <visual name="visual_tower_text_mesh">
      <origin rpy="8.992806499463768e-14 -1.570241143557443 1.5988186561911613" xyz="-0.040617526582081696 4.362558106779257e-06 0.02737731026837054"/>
      <geometry>
        <mesh filename="orcahand_description/assets/urdf/visual/tower_text_mesh.stl" scale="-1 1 1"/>
      </geometry>
      <material name="white"/>
    </visual>
    <collision name="collision_tower_text_mesh">
      <origin rpy="-2.239658800831686 -1.5545672668594075 -2.4480790171423275" xyz="-0.04068345506360967 -0.0011250828560853416 0.027716099517902396"/>
      <geometry>
        <mesh filename="orcahand_description/assets/urdf/collision/tower_text_mesh.stl" scale="-1 1 1"/>
      </geometry>
      <material name="white"/>
    </collision>
  </link>
  <link name="left_world2tower_fixed_jointbody">
    <inertial>
      <origin rpy="0.0 0.0 0.0" xyz="-0.0 0.0 0.0"/>
      <mass value="0.001"/>
      <inertia ixx="1e-09" ixy="0" ixz="0" iyy="1e-09" iyz="0" izz="1e-09"/>
    </inertial>
  </link>
  <link name="left_palm">
    <inertial>
      <origin rpy="1.67519 0.04750000000000032 1.55556" xyz="-0.00193 -0.00052 -0.00664"/>
      <mass value="0.0257"/>
      <inertia ixx="1.612e-05" ixy="0" ixz="0" iyy="1.151e-05" iyz="0" izz="6.72e-06"/>
    </inertial>
    <visual name="visual_palm_mesh">
      <origin rpy="2.01172521777585 0.047179539585598285 1.531383022156099" xyz="-0.0015568393804010381 0.00032366355975666324 -0.011896430343868667"/>
      <geometry>
        <mesh filename="orcahand_description/assets/urdf/visual/palm_mesh.stl" scale="-1 1 1"/>
      </geometry>
      <material name="white"/>
    </visual>
    <collision name="left_collision_palm_mesh">
      <origin rpy="2.026338195778868 0.044917456181218895 1.531847751735018" xyz="-0.0015796019462848588 0.0001376248446814945 -0.011923873250196919"/>
      <geometry>
        <mesh filename="orcahand_description/assets/urdf/collision/palm_mesh.stl" scale="-1 1 1"/>
      </geometry>
      <material name="white"/>
    </collision>
    <visual name="left_visual_palm_skin_mesh">
      <origin rpy="1.7666058493725336 0.1563942094199331 1.6505205003593353" xyz="-0.005673309514830851 -0.0012702684906836111 -0.001744430321194409"/>
      <geometry>
        <mesh filename="orcahand_description/assets/urdf/visual/palm_skin_mesh.stl" scale="-1 1 1"/>
      </geometry>
      <material name="white"/>
    </visual>
    <collision name="left_collision_palm_skin_mesh">
      <origin rpy="1.8840619193629062 0.16785003095386486 1.6839920915628581" xyz="-0.008013832397891144 -0.001293701510845759 -0.0015696747425978242"/>
      <geometry>
        <mesh filename="orcahand_description/assets/urdf/collision/palm_skin_mesh.stl" scale="-1 1 1"/>
      </geometry>
      <material name="white"/>
    </collision>
  </link>
  <link name="left_wrist_jointbody">
    <inertial>
      <origin rpy="0.0 0.0 0.0" xyz="-0.0 0.0 0.0"/>
      <mass value="0.001"/>
      <inertia ixx="1e-09" ixy="0" ixz="0" iyy="1e-09" iyz="0" izz="1e-09"/>
    </inertial>
  </link>
  <link name="left_thumb_mp">
    <inertial>
      <origin rpy="0.0 0.016249999999999876 0.0" xyz="-0.00247 0.0 0.004"/>
      <mass value="0.00586"/>
      <inertia ixx="8.4e-07" ixy="0" ixz="0" iyy="6.6e-07" iyz="0" izz="2.7e-07"/>
    </inertial>
    <visual name="left_visual_thumb_mp_mesh">
      <origin rpy="-0.00450638440425983 -0.0029041941261005455 0.0" xyz="-0.0026672782758389094 -3.6617030073895996e-06 0.0032021510136003503"/>
      <geometry>
        <mesh filename="orcahand_description/assets/urdf/visual/thumb_mp_mesh.stl" scale="-1 1 1"/>
      </geometry>
      <material name="white"/>
    </visual>
    <collision name="left_collision_thumb_mp_mesh">
      <origin rpy="-0.004051421860145692 0.0 0.0" xyz="-0.0025186274059406416 1.1817094343651893e-05 0.0033325772179257306"/>
      <geometry>
        <mesh filename="orcahand_description/assets/urdf/collision/thumb_mp_mesh.stl" scale="-1 1 1"/>
      </geometry>
      <material name="white"/>
    </collision>
  </link>
  <link name="left_thumb_mcp_jointbody">
    <inertial>
      <origin rpy="0.0 0.0 0.0" xyz="-0.0 0.0 0.0"/>
      <mass value="0.001"/>
      <inertia ixx="1e-09" ixy="0" ixz="0" iyy="1e-09" iyz="0" izz="1e-09"/>
    </inertial>
  </link>
  <link name="left_thumb_pp">
    <inertial>
      <origin rpy="1.5708 0.7739199999999999 1.5708" xyz="-0.01848 1e-05 2e-05"/>
      <mass value="0.00655"/>
      <inertia ixx="7.5e-07" ixy="0" ixz="0" iyy="7.1e-07" iyz="0" izz="3e-07"/>
    </inertial>
    <visual name="left_visual_thumb_pp_mesh">
      <origin rpy="-1.6017800681828298 -1.1287165327427504 -1.5432562301164818" xyz="-0.01772057472979195 1.0070925191614284e-05 -0.00010493568910233946"/>
      <geometry>
        <mesh filename="orcahand_description/assets/urdf/visual/thumb_pp_mesh.stl" scale="-1 1 1"/>
      </geometry>
      <material name="white"/>
    </visual>
    <collision name="left_collision_thumb_pp_mesh">
      <origin rpy="-1.588892025872152 -1.3512360913096229 -1.5473903377526785" xyz="-0.01727473106987278 2.0812531064334476e-05 -0.00010892038972696916"/>
      <geometry>
        <mesh filename="orcahand_description/assets/urdf/collision/thumb_pp_mesh.stl" scale="-1 1 1"/>
      </geometry>
      <material name="white"/>
    </collision>
  </link>
  <link name="left_thumb_abd_jointbody">
    <inertial>
      <origin rpy="0.0 0.0 0.0" xyz="-0.0 0.0 0.0"/>
      <mass value="0.001"/>
      <inertia ixx="1e-09" ixy="0" ixz="0" iyy="1e-09" iyz="0" izz="1e-09"/>
    </inertial>
  </link>
  <link name="left_thumb_ip">
    <inertial>
      <origin rpy="0.0003700000000000001 0.03263000000000016 0.00034" xyz="-0.00135 2e-05 0.01383"/>
      <mass value="0.01402"/>
      <inertia ixx="1.7e-06" ixy="0" ixz="0" iyy="1.64e-06" iyz="0" izz="5.9e-07"/>
    </inertial>
    <visual name="left_visual_thumb_ip_mesh">
      <origin rpy="0.0 0.04338716477372251 0.0" xyz="-0.0012998948492342203 7.159773213648307e-06 0.013619877706625217"/>
      <geometry>
        <mesh filename="orcahand_description/assets/urdf/visual/thumb_ip_mesh.stl" scale="-1 1 1"/>
      </geometry>
      <material name="white"/>
    </visual>
    <collision name="left_collision_thumb_ip_mesh">
      <origin rpy="0.00708255798627546 0.04763590113115046 0.0" xyz="-0.0013560375396256981 0.00012710825491742077 0.013446327660739959"/>
      <geometry>
        <mesh filename="orcahand_description/assets/urdf/collision/thumb_ip_mesh.stl" scale="-1 1 1"/>
      </geometry>
      <material name="white"/>
    </collision>
    <visual name="left_visual_thumb_ip_skin_mesh">
      <origin rpy="3.141592653589793 -1.2480960827956862 0.0" xyz="-0.0015424443589898442 1.6522252825510055e-07 0.016259641785170875"/>
      <geometry>
        <mesh filename="orcahand_description/assets/urdf/visual/thumb_ip_skin_mesh.stl" scale="-1 1 1"/>
      </geometry>
      <material name="white"/>
    </visual>
    <collision name="left_collision_thumb_ip_skin_mesh">
      <origin rpy="3.141592653589793 -1.243771833702049 0.0" xyz="-0.0015528244655451595 6.48072440430664e-06 0.016246657621879965"/>
      <geometry>
        <mesh filename="orcahand_description/assets/urdf/collision/thumb_ip_skin_mesh.stl" scale="-1 1 1"/>
      </geometry>
      <material name="white"/>
    </collision>
  </link>
  <link name="left_thumb_pip_jointbody">
    <inertial>
      <origin rpy="0.0 0.0 0.0" xyz="-0.0 0.0 0.0"/>
      <mass value="0.001"/>
      <inertia ixx="1e-09" ixy="0" ixz="0" iyy="1e-09" iyz="0" izz="1e-09"/>
    </inertial>
  </link>
  <link name="left_thumb_dp">
    <inertial>
      <origin rpy="0.00075 0.08211000000000013 0.00013000000000000002" xyz="-0.00233 1e-05 0.01133"/>
      <mass value="0.0132"/>
      <inertia ixx="1.4e-06" ixy="0" ixz="0" iyy="1.37e-06" iyz="0" izz="4.4e-07"/>
    </inertial>
    <visual name="left_visual_thumb_dp_mesh">
      <origin rpy="0.0 0.24698289481892632 0.0" xyz="-0.001737692119750562 -5.352917438125722e-06 0.005127321105400321"/>
      <geometry>
        <mesh filename="orcahand_description/assets/urdf/visual/thumb_dp_mesh.stl" scale="-1 1 1"/>
      </geometry>
      <material name="white"/>
    </visual>
    <collision name="left_collision_thumb_dp_mesh">
      <origin rpy="0.24272423187789072 -0.008190712846545711 1.5687682825082248" xyz="-0.0020244971365026335 3.68319791392775e-05 0.005533677984084769"/>
      <geometry>
        <mesh filename="orcahand_description/assets/urdf/collision/thumb_dp_mesh.stl" scale="-1 1 1"/>
      </geometry>
      <material name="white"/>
    </collision>
    <visual name="left_visual_thumb_dp_skin_mesh">
      <origin rpy="3.141592653589793 -0.40239793279263236 0.0" xyz="-0.002793435568551968 -6.14386555467744e-07 0.016601042013200628"/>
      <geometry>
        <mesh filename="orcahand_description/assets/urdf/visual/thumb_dp_skin_mesh.stl" scale="-1 1 1"/>
      </geometry>
      <material name="white"/>
    </visual>
    <collision name="left_collision_thumb_dp_skin_mesh">
      <origin rpy="3.141592653589793 -0.3963953079219906 0.0" xyz="-0.002785448336058668 -6.944475247259374e-06 0.016557497442018437"/>
      <geometry>
        <mesh filename="orcahand_description/assets/urdf/collision/thumb_dp_skin_mesh.stl" scale="-1 1 1"/>
      </geometry>
      <material name="white"/>
    </collision>
  </link>
  <link name="left_thumb_dip_jointbody">
    <inertial>
      <origin rpy="0.0 0.0 0.0" xyz="-0.0 0.0 0.0"/>
      <mass value="0.001"/>
      <inertia ixx="1e-09" ixy="0" ixz="0" iyy="1e-09" iyz="0" izz="1e-09"/>
    </inertial>
  </link>
  <link name="left_thumb_fingertip">
    <inertial>
      <origin rpy="0.0 0.0 0.0" xyz="0.003 0.0 0.025"/>
      <mass value="0.0"/>
      <inertia ixx="0.0" ixy="0" ixz="0" iyy="0.0" iyz="0" izz="0.0"/>
    </inertial>
  </link>
  <link name="left_index_mp">
    <inertial>
      <origin rpy="-2.6535897932333796e-06 -1.5707926535897931 3.141592653589793" xyz="-0.01155 0.0 -4e-05"/>
      <mass value="0.00498"/>
      <inertia ixx="3.4e-07" ixy="0" ixz="0" iyy="3.1e-07" iyz="0" izz="2e-07"/>
    </inertial>
    <visual name="left_visual_index_mp_mesh">
      <origin rpy="3.1297715721932393 -1.5066740246432395 2.4424906541753444e-15" xyz="-0.010698479000335614 -1.389065483476104e-05 -0.00027878809319396305"/>
      <geometry>
        <mesh filename="orcahand_description/assets/urdf/visual/index_mp_mesh.stl" scale="-1 1 1"/>
      </geometry>
      <material name="white"/>
    </visual>
    <collision name="left_collision_index_mp_mesh">
      <origin rpy="0.928212641576985 -1.5147947849129795 2.212627507721145" xyz="-0.01047824184159959 -4.456734197189478e-05 -0.00016480462181888062"/>
      <geometry>
        <mesh filename="orcahand_description/assets/urdf/collision/index_mp_mesh.stl" scale="-1 1 1"/>
      </geometry>
      <material name="white"/>
    </collision>
  </link>
  <link name="left_index_abd_jointbody">
    <inertial>
      <origin rpy="0.0 0.0 0.0" xyz="-0.0 0.0 0.0"/>
      <mass value="0.001"/>
      <inertia ixx="1e-09" ixy="0" ixz="0" iyy="1e-09" iyz="0" izz="1e-09"/>
    </inertial>
  </link>
  <link name="left_index_pp">
    <inertial>
      <origin rpy="0.00034 0.020550000000000068 0.00038" xyz="-0.00135 2e-05 0.01637"/>
      <mass value="0.0165"/>
      <inertia ixx="2.39e-06" ixy="0" ixz="0" iyy="2.31e-06" iyz="0" izz="7.1e-07"/>
    </inertial>
    <visual name="left_visual_index_pp_mesh">
      <origin rpy="0.005516325755706635 0.035101984887858206 0.03910570256058449" xyz="-0.0012791981098529209 4.322204569499314e-05 0.016098661080179"/>
      <geometry>
        <mesh filename="orcahand_description/assets/urdf/visual/index_pp_mesh.stl" scale="-1 1 1"/>
      </geometry>
      <material name="white"/>
    </visual>
    <collision name="left_collision_index_pp_mesh">
      <origin rpy="0.0 0.042883356216690816 0.0" xyz="-0.0013516740131344841 1.1247422892215125e-05 0.015681803525061735"/>
      <geometry>
        <mesh filename="orcahand_description/assets/urdf/collision/index_pp_mesh.stl" scale="-1 1 1"/>
      </geometry>
      <material name="white"/>
    </collision>
    <visual name="left_visual_index_pp_skin_mesh">
      <origin rpy="3.141592653589793 -0.8345404465359767 0.0" xyz="-0.0016617007377281573 7.13567847691717e-08 0.018763861638214734"/>
      <geometry>
        <mesh filename="orcahand_description/assets/urdf/visual/index_pp_skin_mesh.stl" scale="-1 1 1"/>
      </geometry>
      <material name="white"/>
    </visual>
    <collision name="left_collision_index_pp_skin_mesh">
      <origin rpy="3.141592653589793 -0.8259683678608123 0.0" xyz="-0.0016773866527582534 -5.5310131701629075e-06 0.018740870134460883"/>
      <geometry>
        <mesh filename="orcahand_description/assets/urdf/collision/index_pp_skin_mesh.stl" scale="-1 1 1"/>
      </geometry>
      <material name="white"/>
    </collision>
  </link>
  <link name="left_index_mcp_jointbody">
    <inertial>
      <origin rpy="0.0 0.0 0.0" xyz="-0.0 0.0 0.0"/>
      <mass value="0.001"/>
      <inertia ixx="1e-09" ixy="0" ixz="0" iyy="1e-09" iyz="0" izz="1e-09"/>
    </inertial>
  </link>
  <link name="left_index_ip">
    <inertial>
      <origin rpy="-0.00042000000000000023 -0.18548999999999993 0.004400000000000001" xyz="-0.00071 1e-05 0.01929"/>
      <mass value="0.01521"/>
      <inertia ixx="2.08e-06" ixy="0" ixz="0" iyy="2.06e-06" iyz="0" izz="5.4e-07"/>
    </inertial>
    <visual name="left_visual_index_ip_mesh">
      <origin rpy="-0.03448776902850714 -0.0034390239986910043 1.5709149778710771" xyz="-0.0010416798025929732 7.836534536637715e-05 0.011793743862640304"/>
      <geometry>
        <mesh filename="orcahand_description/assets/urdf/visual/index_ip_mesh.stl" scale="-1 1 1"/>
      </geometry>
      <material name="white"/>
    </visual>
    <collision name="left_collision_index_ip_mesh">
      <origin rpy="0.0018005943049513862 0.0 1.5707963267948966" xyz="-0.001264526142413497 -1.637119615337525e-05 0.01147202326458154"/>
      <geometry>
        <mesh filename="orcahand_description/assets/urdf/collision/index_ip_mesh.stl" scale="-1 1 1"/>
      </geometry>
      <material name="white"/>
    </collision>
    <visual name="left_visual_index_ip_skin_mesh">
      <origin rpy="0.0 -0.4563594541722644 0.0" xyz="-0.0006177579160319044 -2.8394632435300543e-07 0.02298191534250252"/>
      <geometry>
        <mesh filename="orcahand_description/assets/urdf/visual/index_ip_skin_mesh.stl" scale="-1 1 1"/>
      </geometry>
      <material name="white"/>
    </visual>
    <collision name="left_collision_index_ip_skin_mesh">
      <origin rpy="0.0 -0.4457042297154219 0.0" xyz="-0.0006216739383467692 2.432607491983251e-06 0.02302104994067657"/>
      <geometry>
        <mesh filename="orcahand_description/assets/urdf/collision/index_ip_skin_mesh.stl" scale="-1 1 1"/>
      </geometry>
      <material name="white"/>
    </collision>
  </link>
  <link name="left_index_pip_jointbody">
    <inertial>
      <origin rpy="0.0 0.0 0.0" xyz="-0.0 0.0 0.0"/>
      <mass value="0.001"/>
      <inertia ixx="1e-09" ixy="0" ixz="0" iyy="1e-09" iyz="0" izz="1e-09"/>
    </inertial>
  </link>
  <link name="left_index_fingertip">
    <inertial>
      <origin rpy="0.0 0.0 0.0" xyz="0.009 0.0 0.035"/>
      <mass value="0.0"/>
      <inertia ixx="0.0" ixy="0" ixz="0" iyy="0.0" iyz="0" izz="0.0"/>
    </inertial>
  </link>
  <link name="left_middle_mp">
    <inertial>
      <origin rpy="-2.6535897932333796e-06 -1.5707926535897931 3.141592653589793" xyz="-0.01155 0.0 -4e-05"/>
      <mass value="0.00498"/>
      <inertia ixx="3.4e-07" ixy="0" ixz="0" iyy="3.1e-07" iyz="0" izz="2e-07"/>
    </inertial>
    <visual name="left_visual_middle_mp_mesh">
      <origin rpy="3.1297715721932393 -1.5066740246432395 2.4424906541753444e-15" xyz="-0.010698479000335614 -1.389065483476104e-05 -0.00027878809319396305"/>
      <geometry>
        <mesh filename="orcahand_description/assets/urdf/visual/middle_mp_mesh.stl" scale="-1 1 1"/>
      </geometry>
      <material name="white"/>
    </visual>
    <collision name="left_collision_middle_mp_mesh">
      <origin rpy="0.928212641576985 -1.5147947849129795 2.212627507721145" xyz="-0.01047824184159959 -4.456734197189478e-05 -0.00016480462181888062"/>
      <geometry>
        <mesh filename="orcahand_description/assets/urdf/collision/middle_mp_mesh.stl" scale="-1 1 1"/>
      </geometry>
      <material name="white"/>
    </collision>
  </link>
  <link name="left_middle_abd_jointbody">
    <inertial>
      <origin rpy="0.0 0.0 0.0" xyz="-0.0 0.0 0.0"/>
      <mass value="0.001"/>
      <inertia ixx="1e-09" ixy="0" ixz="0" iyy="1e-09" iyz="0" izz="1e-09"/>
    </inertial>
  </link>
  <link name="left_middle_pp">
    <inertial>
      <origin rpy="-2.9999999999999916e-05 0.013859999999999983 0.0005999999999999998" xyz="-0.00144 2e-05 0.02021"/>
      <mass value="0.02006"/>
      <inertia ixx="3.78e-06" ixy="0" ixz="0" iyy="3.69e-06" iyz="0" izz="8.9e-07"/>
    </inertial>
    <visual name="left_visual_middle_pp_mesh">
      <origin rpy="0.004564296284170381 0.027656376334468602 0.037580505677349094" xyz="-0.001283421930192045 3.6963342684240676e-05 0.02022720775953102"/>
      <geometry>
        <mesh filename="orcahand_description/assets/urdf/visual/middle_pp_mesh.stl" scale="-1 1 1"/>
      </geometry>
      <material name="white"/>
    </visual>
    <collision name="left_collision_middle_pp_mesh">
      <origin rpy="-0.0006410664486678006 0.029880005436222712 0.0" xyz="-0.001339380770656077 -6.845101857801683e-06 0.02011933923689832"/>
      <geometry>
        <mesh filename="orcahand_description/assets/urdf/collision/middle_pp_mesh.stl" scale="-1 1 1"/>
      </geometry>
      <material name="white"/>
    </collision>
    <visual name="left_visual_middle_pp_skin_mesh">
      <origin rpy="0.0 -0.22312530126972074 0.0" xyz="-0.001729699116189442 2.0144468929163878e-08 0.022938288977938984"/>
      <geometry>
        <mesh filename="orcahand_description/assets/urdf/visual/middle_pp_skin_mesh.stl" scale="-1 1 1"/>
      </geometry>
      <material name="white"/>
    </visual>
    <collision name="left_collision_middle_pp_skin_mesh">
      <origin rpy="0.0 -0.22006061767397878 0.0" xyz="-0.0017525848624676125 2.7252940732883304e-06 0.022885135333659"/>
      <geometry>
        <mesh filename="orcahand_description/assets/urdf/collision/middle_pp_skin_mesh.stl" scale="-1 1 1"/>
      </geometry>
      <material name="white"/>
    </collision>
  </link>
  <link name="left_middle_mcp_jointbody">
    <inertial>
      <origin rpy="0.0 0.0 0.0" xyz="-0.0 0.0 0.0"/>
      <mass value="0.001"/>
      <inertia ixx="1e-09" ixy="0" ixz="0" iyy="1e-09" iyz="0" izz="1e-09"/>
    </inertial>
  </link>
  <link name="left_middle_ip">
    <inertial>
      <origin rpy="-0.00042000000000000023 -0.18548999999999993 0.004400000000000001" xyz="-0.00071 1e-05 0.01929"/>
      <mass value="0.01521"/>
      <inertia ixx="2.08e-06" ixy="0" ixz="0" iyy="2.06e-06" iyz="0" izz="5.4e-07"/>
    </inertial>
    <visual name="left_visual_middle_ip_mesh">
      <origin rpy="-0.03448776902850714 -0.0034390239986910043 1.5709149778710771" xyz="-0.0010416798025929732 7.836534536637715e-05 0.011793743862640304"/>
      <geometry>
        <mesh filename="orcahand_description/assets/urdf/visual/middle_ip_mesh.stl" scale="-1 1 1"/>
      </geometry>
      <material name="white"/>
    </visual>
    <collision name="left_collision_middle_ip_mesh">
      <origin rpy="0.0018005943049513862 0.0 1.5707963267948966" xyz="-0.001264526142413497 -1.637119615337525e-05 0.01147202326458154"/>
      <geometry>
        <mesh filename="orcahand_description/assets/urdf/collision/middle_ip_mesh.stl" scale="-1 1 1"/>
      </geometry>
      <material name="white"/>
    </collision>
    <visual name="left_visual_middle_ip_skin_mesh">
      <origin rpy="0.0 -0.4563594541722644 0.0" xyz="-0.0006177579160319044 -2.8394632435300543e-07 0.02298191534250252"/>
      <geometry>
        <mesh filename="orcahand_description/assets/urdf/visual/middle_ip_skin_mesh.stl" scale="-1 1 1"/>
      </geometry>
      <material name="white"/>
    </visual>
    <collision name="left_collision_middle_ip_skin_mesh">
      <origin rpy="0.0 -0.4457042297154219 0.0" xyz="-0.0006216739383467692 2.432607491983251e-06 0.02302104994067657"/>
      <geometry>
        <mesh filename="orcahand_description/assets/urdf/collision/middle_ip_skin_mesh.stl" scale="-1 1 1"/>
      </geometry>
      <material name="white"/>
    </collision>
  </link>
  <link name="left_middle_pip_jointbody">
    <inertial>
      <origin rpy="0.0 0.0 0.0" xyz="-0.0 0.0 0.0"/>
      <mass value="0.001"/>
      <inertia ixx="1e-09" ixy="0" ixz="0" iyy="1e-09" iyz="0" izz="1e-09"/>
    </inertial>
  </link>
  <link name="left_middle_fingertip">
    <inertial>
      <origin rpy="0.0 0.0 0.0" xyz="0.009 0.0 0.035"/>
      <mass value="0.0"/>
      <inertia ixx="0.0" ixy="0" ixz="0" iyy="0.0" iyz="0" izz="0.0"/>
    </inertial>
  </link>
  <link name="left_ring_mp">
    <inertial>
      <origin rpy="-2.6535897932333796e-06 -1.5707926535897931 3.141592653589793" xyz="-0.01155 0.0 -4e-05"/>
      <mass value="0.00498"/>
      <inertia ixx="3.4e-07" ixy="0" ixz="0" iyy="3.1e-07" iyz="0" izz="2e-07"/>
    </inertial>
    <visual name="left_visual_ring_mp_mesh">
      <origin rpy="3.1297715721932393 -1.5066740246432395 2.4424906541753444e-15" xyz="-0.010698479000335614 -1.389065483476104e-05 -0.00027878809319396305"/>
      <geometry>
        <mesh filename="orcahand_description/assets/urdf/visual/ring_mp_mesh.stl" scale="-1 1 1"/>
      </geometry>
      <material name="white"/>
    </visual>
    <collision name="left_collision_ring_mp_mesh">
      <origin rpy="0.928212641576985 -1.5147947849129795 2.212627507721145" xyz="-0.01047824184159959 -4.456734197189478e-05 -0.00016480462181888062"/>
      <geometry>
        <mesh filename="orcahand_description/assets/urdf/collision/ring_mp_mesh.stl" scale="-1 1 1"/>
      </geometry>
      <material name="white"/>
    </collision>
  </link>
  <link name="left_ring_abd_jointbody">
    <inertial>
      <origin rpy="0.0 0.0 0.0" xyz="-0.0 0.0 0.0"/>
      <mass value="0.001"/>
      <inertia ixx="1e-09" ixy="0" ixz="0" iyy="1e-09" iyz="0" izz="1e-09"/>
    </inertial>
  </link>
  <link name="left_ring_pp">
    <inertial>
      <origin rpy="-2.9999999999999916e-05 0.013859999999999983 0.0005999999999999998" xyz="-0.00144 2e-05 0.02021"/>
      <mass value="0.02006"/>
      <inertia ixx="3.78e-06" ixy="0" ixz="0" iyy="3.69e-06" iyz="0" izz="8.9e-07"/>
    </inertial>
    <visual name="left_visual_ring_pp_mesh">
      <origin rpy="0.004564296284170381 0.027656376334468602 0.037580505677349094" xyz="-0.001283421930192045 3.6963342684240676e-05 0.02022720775953102"/>
      <geometry>
        <mesh filename="orcahand_description/assets/urdf/visual/ring_pp_mesh.stl" scale="-1 1 1"/>
      </geometry>
      <material name="white"/>
    </visual>
    <collision name="left_collision_ring_pp_mesh">
      <origin rpy="-0.0006410664486678006 0.029880005436222712 0.0" xyz="-0.001339380770656077 -6.845101857801683e-06 0.02011933923689832"/>
      <geometry>
        <mesh filename="orcahand_description/assets/urdf/collision/ring_pp_mesh.stl" scale="-1 1 1"/>
      </geometry>
      <material name="white"/>
    </collision>
    <visual name="left_visual_ring_pp_skin_mesh">
      <origin rpy="0.0 -0.22312530126972074 0.0" xyz="-0.001729699116189442 2.0144468929163878e-08 0.022938288977938984"/>
      <geometry>
        <mesh filename="orcahand_description/assets/urdf/visual/ring_pp_skin_mesh.stl" scale="-1 1 1"/>
      </geometry>
      <material name="white"/>
    </visual>
    <collision name="left_collision_ring_pp_skin_mesh">
      <origin rpy="0.0 -0.22006061767397878 0.0" xyz="-0.0017525848624676125 2.7252940732883304e-06 0.022885135333659"/>
      <geometry>
        <mesh filename="orcahand_description/assets/urdf/collision/ring_pp_skin_mesh.stl" scale="-1 1 1"/>
      </geometry>
      <material name="white"/>
    </collision>
  </link>
  <link name="left_ring_mcp_jointbody">
    <inertial>
      <origin rpy="0.0 0.0 0.0" xyz="-0.0 0.0 0.0"/>
      <mass value="0.001"/>
      <inertia ixx="1e-09" ixy="0" ixz="0" iyy="1e-09" iyz="0" izz="1e-09"/>
    </inertial>
  </link>
  <link name="left_ring_ip">
    <inertial>
      <origin rpy="-0.00042000000000000023 -0.18548999999999993 0.004400000000000001" xyz="-0.00071 1e-05 0.01929"/>
      <mass value="0.01521"/>
      <inertia ixx="2.08e-06" ixy="0" ixz="0" iyy="2.06e-06" iyz="0" izz="5.4e-07"/>
    </inertial>
    <visual name="left_visual_ring_ip_mesh">
      <origin rpy="-0.03448776902850714 -0.0034390239986910043 1.5709149778710771" xyz="-0.0010416798025929732 7.836534536637715e-05 0.011793743862640304"/>
      <geometry>
        <mesh filename="orcahand_description/assets/urdf/visual/ring_ip_mesh.stl" scale="-1 1 1"/>
      </geometry>
      <material name="white"/>
    </visual>
    <collision name="left_collision_ring_ip_mesh">
      <origin rpy="0.0018005943049513862 0.0 1.5707963267948966" xyz="-0.001264526142413497 -1.637119615337525e-05 0.01147202326458154"/>
      <geometry>
        <mesh filename="orcahand_description/assets/urdf/collision/ring_ip_mesh.stl" scale="-1 1 1"/>
      </geometry>
      <material name="white"/>
    </collision>
    <visual name="left_visual_ring_ip_skin_mesh">
      <origin rpy="0.0 -0.4563594541722644 0.0" xyz="-0.0006177579160319044 -2.8394632435300543e-07 0.02298191534250252"/>
      <geometry>
        <mesh filename="orcahand_description/assets/urdf/visual/ring_ip_skin_mesh.stl" scale="-1 1 1"/>
      </geometry>
      <material name="white"/>
    </visual>
    <collision name="left_collision_ring_ip_skin_mesh">
      <origin rpy="0.0 -0.4457042297154219 0.0" xyz="-0.0006216739383467692 2.432607491983251e-06 0.02302104994067657"/>
      <geometry>
        <mesh filename="orcahand_description/assets/urdf/collision/ring_ip_skin_mesh.stl" scale="-1 1 1"/>
      </geometry>
      <material name="white"/>
    </collision>
  </link>
  <link name="left_ring_pip_jointbody">
    <inertial>
      <origin rpy="0.0 0.0 0.0" xyz="-0.0 0.0 0.0"/>
      <mass value="0.001"/>
      <inertia ixx="1e-09" ixy="0" ixz="0" iyy="1e-09" iyz="0" izz="1e-09"/>
    </inertial>
  </link>
  <link name="left_ring_fingertip">
    <inertial>
      <origin rpy="0.0 0.0 0.0" xyz="0.009 0.0 0.035"/>
      <mass value="0.0"/>
      <inertia ixx="0.0" ixy="0" ixz="0" iyy="0.0" iyz="0" izz="0.0"/>
    </inertial>
  </link>
  <link name="left_pinky_mp">
    <inertial>
      <origin rpy="-2.6535897932333796e-06 -1.5707926535897931 3.141592653589793" xyz="-0.01155 0.0 -4e-05"/>
      <mass value="0.00498"/>
      <inertia ixx="3.4e-07" ixy="0" ixz="0" iyy="3.1e-07" iyz="0" izz="2e-07"/>
    </inertial>
    <visual name="left_visual_pinky_mp_mesh">
      <origin rpy="3.1297715721932393 -1.5066740246432395 2.4424906541753444e-15" xyz="-0.010698479000335614 -1.389065483476104e-05 -0.00027878809319396305"/>
      <geometry>
        <mesh filename="orcahand_description/assets/urdf/visual/pinky_mp_mesh.stl" scale="-1 1 1"/>
      </geometry>
      <material name="white"/>
    </visual>
    <collision name="left_collision_pinky_mp_mesh">
      <origin rpy="0.928212641576985 -1.5147947849129795 2.212627507721145" xyz="-0.01047824184159959 -4.456734197189478e-05 -0.00016480462181888062"/>
      <geometry>
        <mesh filename="orcahand_description/assets/urdf/collision/pinky_mp_mesh.stl" scale="-1 1 1"/>
      </geometry>
      <material name="white"/>
    </collision>
  </link>
  <link name="left_pinky_abd_jointbody">
    <inertial>
      <origin rpy="0.0 0.0 0.0" xyz="-0.0 0.0 0.0"/>
      <mass value="0.001"/>
      <inertia ixx="1e-09" ixy="0" ixz="0" iyy="1e-09" iyz="0" izz="1e-09"/>
    </inertial>
  </link>
  <link name="left_pinky_pp">
    <inertial>
      <origin rpy="0.0003700000000000001 0.03263000000000016 0.00034" xyz="-0.00135 2e-05 0.01383"/>
      <mass value="0.01402"/>
      <inertia ixx="1.7e-06" ixy="0" ixz="0" iyy="1.64e-06" iyz="0" izz="5.9e-07"/>
    </inertial>
    <visual name="left_visual_pinky_pp_mesh">
      <origin rpy="0.0 0.04338716477372251 0.0" xyz="-0.0012998948492342203 7.159773213648307e-06 0.013619877706625217"/>
      <geometry>
        <mesh filename="orcahand_description/assets/urdf/visual/pinky_pp_mesh.stl" scale="-1 1 1"/>
      </geometry>
      <material name="white"/>
    </visual>
    <collision name="left_collision_pinky_pp_mesh">
      <origin rpy="0.00708255798627546 0.04763590113115046 0.0" xyz="-0.0013560375396256981 0.00012710825491742077 0.013446327660739959"/>
      <geometry>
        <mesh filename="orcahand_description/assets/urdf/collision/pinky_pp_mesh.stl" scale="-1 1 1"/>
      </geometry>
      <material name="white"/>
    </collision>
    <visual name="left_visual_pinky_pp_skin_mesh">
      <origin rpy="3.141592653589793 -1.2480960827956862 0.0" xyz="-0.0015424443589898442 1.6522252825510055e-07 0.016259641785170875"/>
      <geometry>
        <mesh filename="orcahand_description/assets/urdf/visual/pinky_pp_skin_mesh.stl" scale="-1 1 1"/>
      </geometry>
      <material name="white"/>
    </visual>
    <collision name="left_collision_pinky_pp_skin_mesh">
      <origin rpy="3.141592653589793 -1.243771833702049 0.0" xyz="-0.0015528244655451595 6.48072440430664e-06 0.016246657621879965"/>
      <geometry>
        <mesh filename="orcahand_description/assets/urdf/collision/pinky_pp_skin_mesh.stl" scale="-1 1 1"/>
      </geometry>
      <material name="white"/>
    </collision>
  </link>
  <link name="left_pinky_mcp_jointbody">
    <inertial>
      <origin rpy="0.0 0.0 0.0" xyz="-0.0 0.0 0.0"/>
      <mass value="0.001"/>
      <inertia ixx="1e-09" ixy="0" ixz="0" iyy="1e-09" iyz="0" izz="1e-09"/>
    </inertial>
  </link>
  <link name="left_pinky_ip">
    <inertial>
      <origin rpy="-0.00042000000000000023 -0.18548999999999993 0.004400000000000001" xyz="-0.00071 1e-05 0.01929"/>
      <mass value="0.01521"/>
      <inertia ixx="2.08e-06" ixy="0" ixz="0" iyy="2.06e-06" iyz="0" izz="5.4e-07"/>
    </inertial>
    <visual name="left_visual_pinky_ip_mesh">
      <origin rpy="-0.03448776902850714 -0.0034390239986910043 1.5709149778710771" xyz="-0.0010416798025929732 7.836534536637715e-05 0.011793743862640304"/>
      <geometry>
        <mesh filename="orcahand_description/assets/urdf/visual/pinky_ip_mesh.stl" scale="-1 1 1"/>
      </geometry>
      <material name="white"/>
    </visual>
    <collision name="left_collision_pinky_ip_mesh">
      <origin rpy="0.0018005943049513862 0.0 1.5707963267948966" xyz="-0.001264526142413497 -1.637119615337525e-05 0.01147202326458154"/>
      <geometry>
        <mesh filename="orcahand_description/assets/urdf/collision/pinky_ip_mesh.stl" scale="-1 1 1"/>
      </geometry>
      <material name="white"/>
    </collision>
    <visual name="left_visual_pinky_ip_skin_mesh">
      <origin rpy="0.0 -0.4563594541722644 0.0" xyz="-0.0006177579160319044 -2.8394632435300543e-07 0.02298191534250252"/>
      <geometry>
        <mesh filename="orcahand_description/assets/urdf/visual/pinky_ip_skin_mesh.stl" scale="-1 1 1"/>
      </geometry>
      <material name="white"/>
    </visual>
    <collision name="left_collision_pinky_ip_skin_mesh">
      <origin rpy="0.0 -0.4457042297154219 0.0" xyz="-0.0006216739383467692 2.432607491983251e-06 0.02302104994067657"/>
      <geometry>
        <mesh filename="orcahand_description/assets/urdf/collision/pinky_ip_skin_mesh.stl" scale="-1 1 1"/>
      </geometry>
      <material name="white"/>
    </collision>
  </link>
  <link name="left_pinky_pip_jointbody">
    <inertial>
      <origin rpy="0.0 0.0 0.0" xyz="-0.0 0.0 0.0"/>
      <mass value="0.001"/>
      <inertia ixx="1e-09" ixy="0" ixz="0" iyy="1e-09" iyz="0" izz="1e-09"/>
    </inertial>
  </link>
  <link name="left_pinky_fingertip">
    <inertial>
      <origin rpy="0.0 0.0 0.0" xyz="0.009 0.0 0.035"/>
      <mass value="0.0"/>
      <inertia ixx="0.0" ixy="0" ixz="0" iyy="0.0" iyz="0" izz="0.0"/>
    </inertial>
  </link>
  <joint name="left_world2tower_fixed" type="fixed">
    <parent link="left_root"/>
    <child link="left_world2tower_fixed_jointbody"/>
    <origin rpy="0.0 -0.0 -0.0" xyz="0.04 0.0 0.04575"/>
  </joint>
  <joint name="left_world2tower_fixed_offset" type="fixed">
    <parent link="left_world2tower_fixed_jointbody"/>
    <child link="left_tower"/>
    <origin rpy="0.0 -0.0 -0.0" xyz="0.0 -0.0 -0.0"/>
  </joint>
  <joint name="left_wrist" type="revolute">
    <parent link="left_tower"/>
    <child link="left_wrist_jointbody"/>
    <origin rpy="0.0 -0.0 -0.0" xyz="-0.04063 0.0 0.10486999999999999"/>
    <axis xyz="-1.0 0.0 0.0"/>
    <limit effort="100" lower="-0.872665" upper="0.523599" velocity="100"/>
  </joint>
  <joint name="left_wrist_offset" type="fixed">
    <parent link="left_wrist_jointbody"/>
    <child link="left_palm"/>
    <origin rpy="0.0 -0.0 -0.0" xyz="0.002 0.00144 0.03872"/>
  </joint>
  <joint name="left_thumb_mcp" type="revolute">
    <parent link="left_palm"/>
    <child link="left_thumb_mcp_jointbody"/>
    <origin rpy="0.5385700000000002 0.05594999999999972 1.27047" xyz="0.02821 0.01777 -0.01321"/>
    <axis xyz="-0.0 0.0 -1.0"/>
    <limit effort="100" lower="-0.87266" upper="0.87266" velocity="100"/>
  </joint>
  <joint name="left_thumb_mcp_offset" type="fixed">
    <parent link="left_thumb_mcp_jointbody"/>
    <child link="left_thumb_mp"/>
    <origin rpy="0.0 -0.0 -0.0" xyz="0.0 -0.0 -0.0"/>
  </joint>
  <joint name="left_thumb_abd" type="revolute">
    <parent link="left_thumb_mp"/>
    <child link="left_thumb_abd_jointbody"/>
    <origin rpy="-1.22173 -0.0 -0.0" xyz="-6.938893903907228e-18 0.0 0.0"/>
    <axis xyz="-0.0 0.34202085907197166 0.9396923602752502"/>
    <limit effort="100" lower="-0.349066" upper="0.733038" velocity="100"/>
  </joint>
  <joint name="left_thumb_abd_offset" type="fixed">
    <parent link="left_thumb_abd_jointbody"/>
    <child link="left_thumb_pp"/>
    <origin rpy="0.0 -0.0 -0.0" xyz="0.03 -0.0 -0.0"/>
  </joint>
  <joint name="left_thumb_pip" type="revolute">
    <parent link="left_thumb_pp"/>
    <child link="left_thumb_pip_jointbody"/>
    <origin rpy="-2.6535897934554242e-06 -1.5707926535897934 -3.141592653589793" xyz="-0.0 0.0 0.0"/>
    <axis xyz="-0.0 -1.0 0.0"/>
    <limit effort="100" lower="-0.209440" upper="1.884956" velocity="100"/>
  </joint>
  <joint name="left_thumb_pip_offset" type="fixed">
    <parent link="left_thumb_pip_jointbody"/>
    <child link="left_thumb_ip"/>
    <origin rpy="0.0 -0.0 -0.0" xyz="0.0 -0.0 -0.0"/>
  </joint>
  <joint name="left_thumb_dip" type="revolute">
    <parent link="left_thumb_ip"/>
    <child link="left_thumb_dip_jointbody"/>
    <origin rpy="0.0 -0.0 -0.0" xyz="-0.0005 0.0 0.033"/>
    <axis xyz="-0.0 -1.0 0.0"/>
    <limit effort="100" lower="-0.349066" upper="1.954769" velocity="100"/>
  </joint>
  <joint name="left_thumb_dip_offset" type="fixed">
    <parent link="left_thumb_dip_jointbody"/>
    <child link="left_thumb_dp"/>
    <origin rpy="0.0 -0.0 -0.0" xyz="0.0 -0.0 -0.0"/>
  </joint>
  <joint name="left_thumb_dp2thumb_fingertip_fixed_offset" type="fixed">
    <parent link="left_thumb_dp"/>
    <child link="left_thumb_fingertip"/>
    <origin rpy="0.0 -0.0 -0.0" xyz="0.003 0.0 0.025"/>
  </joint>
  <joint name="left_index_abd" type="revolute">
    <parent link="left_palm"/>
    <child link="left_index_abd_jointbody"/>
    <origin rpy="1.6066999999999996 -1.13552 0.05339000000000049" xyz="0.024088797002689358 0.0018999642829399502 0.025164928786148736"/>
    <axis xyz="-0.0 0.0 -1.0"/>
    <limit effort="100" lower="-0.645772" upper="0.645772" velocity="100"/>
  </joint>
  <joint name="left_index_abd_offset" type="fixed">
    <parent link="left_index_abd_jointbody"/>
    <child link="left_index_mp"/>
    <origin rpy="0.0 -0.0 -0.0" xyz="0.02 -0.0 -0.0"/>
  </joint>
  <joint name="left_index_mcp" type="revolute">
    <parent link="left_index_mp"/>
    <child link="left_index_mcp_jointbody"/>
    <origin rpy="3.141592653589793 1.5707926535897931 -3.141592653589793" xyz="-0.0 0.0 0.0"/>
    <axis xyz="-0.0 -1.0 0.0"/>
    <limit effort="100" lower="-0.349066" upper="1.658063" velocity="100"/>
  </joint>
  <joint name="left_index_mcp_offset" type="fixed">
    <parent link="left_index_mcp_jointbody"/>
    <child link="left_index_pp"/>
    <origin rpy="0.0 -0.0 -0.0" xyz="0.0 -0.0 -0.0"/>
  </joint>
  <joint name="left_index_pip" type="revolute">
    <parent link="left_index_pp"/>
    <child link="left_index_pip_jointbody"/>
    <origin rpy="0.0 -0.0 -0.0" xyz="-0.0005 0.0 0.038"/>
    <axis xyz="-0.0 -1.0 0.0"/>
    <limit effort="100" lower="-0.349066" upper="1.884956" velocity="100"/>
  </joint>
  <joint name="left_index_pip_offset" type="fixed">
    <parent link="left_index_pip_jointbody"/>
    <child link="left_index_ip"/>
    <origin rpy="0.0 -0.0 -0.0" xyz="0.0 -0.0 -0.0"/>
  </joint>
  <joint name="left_index_ip2index_fingertip_fixed_offset" type="fixed">
    <parent link="left_index_ip"/>
    <child link="left_index_fingertip"/>
    <origin rpy="0.0 -0.0 -0.0" xyz="0.009 0.0 0.035"/>
  </joint>
  <joint name="left_middle_abd" type="revolute">
    <parent link="left_palm"/>
    <child link="left_middle_abd_jointbody"/>
    <origin rpy="-1.5707926536208807 -1.5707926535897934 -3.141592653558706" xyz="7.346410206776621e-08 0.0 0.030000000000134926"/>
    <axis xyz="-0.0 0.0 -1.0"/>
    <limit effort="100" lower="-0.645772" upper="0.645772" velocity="100"/>
  </joint>
  <joint name="left_middle_abd_offset" type="fixed">
    <parent link="left_middle_abd_jointbody"/>
    <child link="left_middle_mp"/>
    <origin rpy="0.0 -0.0 -0.0" xyz="0.02 -0.0 -0.0"/>
  </joint>
  <joint name="left_middle_mcp" type="revolute">
    <parent link="left_middle_mp"/>
    <child link="left_middle_mcp_jointbody"/>
    <origin rpy="3.141592653589793 1.5707926535897931 -3.141592653589793" xyz="-0.0 0.0 0.0"/>
    <axis xyz="-0.0 -1.0 0.0"/>
    <limit effort="100" lower="-0.349066" upper="1.588250" velocity="100"/>
  </joint>
  <joint name="left_middle_mcp_offset" type="fixed">
    <parent link="left_middle_mcp_jointbody"/>
    <child link="left_middle_pp"/>
    <origin rpy="0.0 -0.0 -0.0" xyz="0.0 -0.0 -0.0"/>
  </joint>
  <joint name="left_middle_pip" type="revolute">
    <parent link="left_middle_pp"/>
    <child link="left_middle_pip_jointbody"/>
    <origin rpy="0.0 -0.0 -0.0" xyz="-0.0005 0.0 0.046"/>
    <axis xyz="-0.0 -1.0 0.0"/>
    <limit effort="100" lower="-0.349066" upper="1.867502" velocity="100"/>
  </joint>
  <joint name="left_middle_pip_offset" type="fixed">
    <parent link="left_middle_pip_jointbody"/>
    <child link="left_middle_ip"/>
    <origin rpy="0.0 -0.0 -0.0" xyz="0.0 -0.0 -0.0"/>
  </joint>
  <joint name="left_middle_ip2middle_fingertip_fixed_offset" type="fixed">
    <parent link="left_middle_ip"/>
    <child link="left_middle_fingertip"/>
    <origin rpy="0.0 -0.0 -0.0" xyz="0.009 0.0 0.035"/>
  </joint>
  <joint name="left_ring_abd" type="revolute">
    <parent link="left_palm"/>
    <child link="left_ring_abd_jointbody"/>
    <origin rpy="-1.5359699999999998 -1.30836 3.05441" xyz="-0.021521022061295733 0.0015382095479525787 0.020824784431525818"/>
    <axis xyz="-0.0 0.0 -1.0"/>
    <limit effort="100" lower="-0.645772" upper="0.645772" velocity="100"/>
  </joint>
  <joint name="left_ring_abd_offset" type="fixed">
    <parent link="left_ring_abd_jointbody"/>
    <child link="left_ring_mp"/>
    <origin rpy="0.0 -0.0 -0.0" xyz="0.02 -0.0 -0.0"/>
  </joint>
  <joint name="left_ring_mcp" type="revolute">
    <parent link="left_ring_mp"/>
    <child link="left_ring_mcp_jointbody"/>
    <origin rpy="3.141592653589793 1.5707926535897931 -3.141592653589793" xyz="-0.0 0.0 0.0"/>
    <axis xyz="-0.0 -1.0 0.0"/>
    <limit effort="100" lower="-0.349066" upper="1.588250" velocity="100"/>
  </joint>
  <joint name="left_ring_mcp_offset" type="fixed">
    <parent link="left_ring_mcp_jointbody"/>
    <child link="left_ring_pp"/>
    <origin rpy="0.0 -0.0 -0.0" xyz="0.0 -0.0 -0.0"/>
  </joint>
  <joint name="left_ring_pip" type="revolute">
    <parent link="left_ring_pp"/>
    <child link="left_ring_pip_jointbody"/>
    <origin rpy="0.0 -0.0 -0.0" xyz="-0.0005 0.0 0.046"/>
    <axis xyz="-0.0 -1.0 0.0"/>
    <limit effort="100" lower="-0.349066" upper="1.867502" velocity="100"/>
  </joint>
  <joint name="left_ring_pip_offset" type="fixed">
    <parent link="left_ring_pip_jointbody"/>
    <child link="left_ring_ip"/>
    <origin rpy="0.0 -0.0 -0.0" xyz="0.0 -0.0 -0.0"/>
  </joint>
  <joint name="left_ring_ip2ring_fingertip_fixed_offset" type="fixed">
    <parent link="left_ring_ip"/>
    <child link="left_ring_fingertip"/>
    <origin rpy="0.0 -0.0 -0.0" xyz="0.009 0.0 0.035"/>
  </joint>
  <joint name="left_pinky_abd" type="revolute">
    <parent link="left_palm"/>
    <child link="left_pinky_abd_jointbody"/>
    <origin rpy="-1.49694 -0.8614899999999999 2.8837299999999995" xyz="-0.04258452932438962 0.004988143142003794 0.007243722937596895"/>
    <axis xyz="-0.0 0.0 -1.0"/>
    <limit effort="100" lower="-0.645772" upper="0.645772" velocity="100"/>
  </joint>
  <joint name="left_pinky_abd_offset" type="fixed">
    <parent link="left_pinky_abd_jointbody"/>
    <child link="left_pinky_mp"/>
    <origin rpy="0.0 -0.0 -0.0" xyz="0.02 -0.0 -0.0"/>
  </joint>
  <joint name="left_pinky_mcp" type="revolute">
    <parent link="left_pinky_mp"/>
    <child link="left_pinky_mcp_jointbody"/>
    <origin rpy="3.141592653589793 1.5707926535897931 -3.141592653589793" xyz="-0.0 0.0 0.0"/>
    <axis xyz="-0.0 -1.0 0.0"/>
    <limit effort="100" lower="-0.349066" upper="1.710423" velocity="100"/>
  </joint>
  <joint name="left_pinky_mcp_offset" type="fixed">
    <parent link="left_pinky_mcp_jointbody"/>
    <child link="left_pinky_pp"/>
    <origin rpy="0.0 -0.0 -0.0" xyz="0.0 -0.0 -0.0"/>
  </joint>
  <joint name="left_pinky_pip" type="revolute">
    <parent link="left_pinky_pp"/>
    <child link="left_pinky_pip_jointbody"/>
    <origin rpy="0.0 -0.0 -0.0" xyz="-0.0005 0.0 0.033"/>
    <axis xyz="-0.0 -1.0 0.0"/>
    <limit effort="100" lower="-0.349066" upper="1.884956" velocity="100"/>
  </joint>
  <joint name="left_pinky_pip_offset" type="fixed">
    <parent link="left_pinky_pip_jointbody"/>
    <child link="left_pinky_ip"/>
    <origin rpy="0.0 -0.0 -0.0" xyz="0.0 -0.0 -0.0"/>
  </joint>
  <joint name="left_pinky_ip2pinky_fingertip_fixed_offset" type="fixed">
    <parent link="left_pinky_ip"/>
    <child link="left_pinky_fingertip"/>
    <origin rpy="0.0 -0.0 -0.0" xyz="0.009 0.0 0.035"/>
  </joint>
  <joint name="panda_link8_to_left_hand" type="fixed">
    <parent link="panda_link8"/>
    <child link="left_root"/>
    <origin xyz="0 0 0" rpy="0 0 0"/>
  </joint>
</robot>